Workbook

Sheet TX_PENJUALAN
A1: tx_id | B1: created_at | C1: updated_at | D1: status | E1: periode_tahun | F1: periode_bulan | G1: tanggal_bukti | H1: panen_kg | I1: harga | J1: jumlah | K1: keterangan | L1: sumber_file | M1: source_row | N1: panen_ke | O1: batch_id
A2: V3-JUAL-2026-01-0001 | B2: 2026-06-07T12:09:16.098Z | C2: 2026-06-07T12:09:16.098Z | D2: active | E2: 2026 | F2: 1 | G2: 46013 | H2: 3753 | I2: 3080 | J2: 11559240 | K2: Januari PANEN 1 | L2: BUKIT PRAGO - 2026 / harian | M2: 2 | N2: 1
A3: V3-JUAL-2026-01-0002 | B3: 2026-06-07T12:09:16.098Z | C3: 2026-06-07T12:09:16.098Z | D3: active | E3: 2026 | F3: 1 | G3: 46013 | H3: 3194 | I3: 3080 | J3: 9837520 | K3: Januari PANEN 1 | L3: BUKIT PRAGO - 2026 / harian | M3: 3 | N3: 1
A4: V3-JUAL-2026-01-0003 | B4: 2026-06-07T12:09:16.098Z | C4: 2026-06-07T12:09:16.098Z | D4: active | E4: 2026 | F4: 1 | G4: 46013 | H4: 6230 | I4: 3080 | J4: 19188400 | K4: Januari PANEN 1 | L4: BUKIT PRAGO - 2026 / harian | M4: 4 | N4: 1
A5: V3-JUAL-2026-01-0004 | B5: 2026-06-07T12:09:16.098Z | C5: 2026-06-07T12:09:16.098Z | D5: active | E5: 2026 | F5: 1 | G5: 46013 | H5: 4754 | I5: 3080 | J5: 14642320 | K5: Januari PANEN 1 | L5: BUKIT PRAGO - 2026 / harian | M5: 5 | N5: 1
A6: V3-JUAL-2026-01-0005 | B6: 2026-06-07T12:09:16.098Z | C6: 2026-06-07T12:09:16.098Z | D6: active | E6: 2026 | F6: 1 | G6: 46013 | H6: 3822 | I6: 3060 | J6: 11695320 | K6: Januari PANEN 1 | L6: BUKIT PRAGO - 2026 / harian | M6: 6 | N6: 1
A7: V3-JUAL-2026-01-0006 | B7: 2026-06-07T12:09:16.102Z | C7: 2026-06-07T12:09:16.102Z | D7: active | E7: 2026 | F7: 1 | G7: 46026 | H7: 5278 | I7: 3080 | J7: 16256240 | K7: Januari PANEN 2 | L7: BUKIT PRAGO - 2026 / harian | M7: 20 | N7: 2
A8: V3-JUAL-2026-01-0007 | B8: 2026-06-07T12:09:16.102Z | C8: 2026-06-07T12:09:16.102Z | D8: active | E8: 2026 | F8: 1 | G8: 46026 | H8: 5392 | I8: 3080 | J8: 16607360 | K8: Januari PANEN 2 | L8: BUKIT PRAGO - 2026 / harian | M8: 21 | N8: 2
A9: V3-JUAL-2026-01-0008 | B9: 2026-06-07T12:09:16.102Z | C9: 2026-06-07T12:09:16.102Z | D9: active | E9: 2026 | F9: 1 | G9: 46026 | H9: 4511 | I9: 3050 | J9: 13758550 | K9: Januari PANEN 2 | L9: BUKIT PRAGO - 2026 / harian | M9: 22 | N9: 2
A10: V3-JUAL-2026-01-0009 | B10: 2026-06-07T12:09:16.102Z | C10: 2026-06-07T12:09:16.102Z | D10: active | E10: 2026 | F10: 1 | G10: 46026 | H10: 3026 | I10: 3050 | J10: 9229300 | K10: Januari PANEN 2 | L10: BUKIT PRAGO - 2026 / harian | M10: 23 | N10: 2
A11: V3-JUAL-2026-02-0001 | B11: 2026-06-07T12:09:16.105Z | C11: 2026-06-07T12:09:16.106Z | D11: active | E11: 2026 | F11: 1 | G11: 46041 | H11: 3464 | I11: 3070 | J11: 10634480 | K11: Januari PANEN 3 | L11: BUKIT PRAGO - 2026 / harian | M11: 38 | N11: 3
A12: V3-JUAL-2026-02-0002 | B12: 2026-06-07T12:09:16.106Z | C12: 2026-06-07T12:09:16.106Z | D12: active | E12: 2026 | F12: 1 | G12: 46041 | H12: 2172 | I12: 3090 | J12: 6711480 | K12: Januari PANEN 3 | L12: BUKIT PRAGO - 2026 / harian | M12: 39 | N12: 3
A13: V3-JUAL-2026-02-0003 | B13: 2026-06-07T12:09:16.106Z | C13: 2026-06-07T12:09:16.106Z | D13: active | E13: 2026 | F13: 1 | G13: 46041 | H13: 5287 | I13: 3090 | J13: 16336830 | K13: Januari PANEN 3 | L13: BUKIT PRAGO - 2026 / harian | M13: 40 | N13: 3
... A54: V3-JUAL-2026-06-0008 | B54: 2026-06-07T12:09:16.128Z | C54: 2026-06-07T12:09:16.128Z | D54: active | E54: 2026 | F54: 6 | G54: 46179 | H54: 6849 | I54: 3400 | J54: 23286600 | K54: Juni PANEN 1 | L54: BUKIT PRAGO - 2026 / harian | M54: 203 | N54: 1
A55: PNJ_V3INPUT_2026_6_PANEN2_20260618_222734_001 | B55: 46191.936 | D55: active | E55: 2026 | F55: 6 | G55: 46191 | H55: 5732 | I55: 3450 | J55: 19775400 | K55: Juni PANEN 2 | M55: INPUT_SHEET_V3 | N55: 2 | O55: V3INPUT_2026_6_PANEN2_20260618_222734
A56: PNJ_V3INPUT_2026_6_PANEN2_20260618_222734_002 | B56: 46191.936 | D56: active | E56: 2026 | F56: 6 | G56: 46191 | H56: 4449 | I56: 3450 | J56: 15349050 | K56: Juni PANEN 2 | M56: INPUT_SHEET_V3 | N56: 2 | O56: V3INPUT_2026_6_PANEN2_20260618_222734
A57: PNJ_V3INPUT_2026_6_PANEN2_20260618_222734_003 | B57: 46191.936 | D57: active | E57: 2026 | F57: 6 | G57: 46191 | H57: 4772 | I57: 3390 | J57: 16177080 | K57: Juni PANEN 2 | M57: INPUT_SHEET_V3 | N57: 2 | O57: V3INPUT_2026_6_PANEN2_20260618_222734
A58: PNJ_V3INPUT_2026_6_PANEN2_20260618_222734_004 | B58: 46191.936 | D58: active | E58: 2026 | F58: 6 | G58: 46191 | H58: 4651 | I58: 3390 | J58: 15766890 | K58: Juni PANEN 2 | M58: INPUT_SHEET_V3 | N58: 2 | O58: V3INPUT_2026_6_PANEN2_20260618_222734
A59: PNJ_V3INPUT_2026_6_PANEN2_20260618_222734_005 | B59: 46191.936 | D59: active | E59: 2026 | F59: 6 | G59: 46191 | H59: 4914 | I59: 3390 | J59: 16658460 | K59: Juni PANEN 2 | M59: INPUT_SHEET_V3 | N59: 2 | O59: V3INPUT_2026_6_PANEN2_20260618_222734
A60: PNJ_V3INPUT_2026_7_PANEN1_20260702_210109_001 | B60: 46205.876 | D60: active | E60: 2026 | F60: 7 | G60: 46205 | H60: 6208 | I60: 3420 | J60: 21231360 | K60: Juli PANEN 1 | M60: INPUT_SHEET_V3 | N60: 1 | O60: V3INPUT_2026_7_PANEN1_20260702_210109
A61: PNJ_V3INPUT_2026_7_PANEN1_20260702_210109_002 | B61: 46205.876 | D61: active | E61: 2026 | F61: 7 | G61: 46205 | H61: 5894 | I61: 3420 | J61: 20157480 | K61: Juli PANEN 1 | M61: INPUT_SHEET_V3 | N61: 1 | O61: V3INPUT_2026_7_PANEN1_20260702_210109
A62: PNJ_V3INPUT_2026_7_PANEN1_20260702_210109_003 | B62: 46205.876 | D62: active | E62: 2026 | F62: 7 | G62: 46205 | H62: 5665 | I62: 3390 | J62: 19204350 | K62: Juli PANEN 1 | M62: INPUT_SHEET_V3 | N62: 1 | O62: V3INPUT_2026_7_PANEN1_20260702_210109
A63: PNJ_V3INPUT_2026_7_PANEN1_20260702_210109_004 | B63: 46205.876 | D63: active | E63: 2026 | F63: 7 | G63: 46205 | H63: 2886 | I63: 3390 | J63: 9783540 | K63: Juli PANEN 1 | M63: INPUT_SHEET_V3 | N63: 1 | O63: V3INPUT_2026_7_PANEN1_20260702_210109
A64: PNJ_V3INPUT_2026_7_PANEN1_20260702_210109_005 | B64: 46205.876 | D64: active | E64: 2026 | F64: 7 | G64: 46205 | H64: 3792 | I64: 3390 | J64: 12854880 | K64: Juli PANEN 1 | M64: INPUT_SHEET_V3 | N64: 1 | O64: V3INPUT_2026_7_PANEN1_20260702_210109
A65: PNJ_V3INPUT_2026_7_PANEN1_20260702_210109_006 | B65: 46205.876 | D65: active | E65: 2026 | F65: 7 | G65: 46205 | H65: 6230 | I65: 3390 | J65: 21119700 | K65: Juli PANEN 1 | M65: INPUT_SHEET_V3 | N65: 1 | O65: V3INPUT_2026_7_PANEN1_20260702_210109

Sheet TARGET_PRODUKSI
A1: tahun | B1: target_kg | C1: jan_kg | D1: feb_kg | E1: mar_kg | F1: apr_kg | G1: mei_kg | H1: jun_kg | I1: jul_kg | J1: agu_kg | K1: sep_kg | L1: okt_kg | M1: nov_kg | N1: des_kg | O1: target_source | P1: recommendation_level | Q1: analysis_years | R1: analysis_quality | S1: analysis_snapshot_json | T1: analysis_updated_at | U1: smart_version | V1: keterangan | W1: status | X1: created_at | Y1: updated_at
A2: 2026 | B2: 604700 | C2: 33982 | D2: 31918 | E2: 36923 | F2: 56436 | G2: 52247 | H2: 47439 | I2: 48319 | J2: 47415 | K2: 54648 | L2: 73547 | M2: 56235 | N2: 65591 | O2: ensemble_trend_seasonal | P2: optimistic | Q2: 2024.2025 | R2: rendah | S2: {"ok":true,"nonBlocking":true,"targetYear":2026,"smartVersion":"V3_TARGET_ENSEMBLE_MONTHLY_BACKTEST_SAFE","mode":"FALLBACK_2_YEAR_ADAPTIVE","quality":"rendah","yearsUsed":[2024,2025],"annuals":[{"year":2024,"totalKg":331247,"monthlyKg":[18225,15406,19273,20907,32432,29426,26774,22783,25738,57226,29735,33322],"source":"ARCHIVE_PENJUALAN"},{"year":2025,"totalKg":481232,"monthlyKg":[26186,24732,28556,57628,39913,34177,37218,38636,46834,47935,44201,55216],"source":"ARCHIVE_PENJUALAN"}],"totalHistoryKg":812479,"monthlyWeights":[0.0561958174904943,0.052783269961977186,0.06106083650190114,0.09332889733840304,0.08640114068441064,0.07845057034220532,0.07990494296577946,0.0784106463878327,0.09037262357414448,0.1216254752851711,0.09299619771863119,0.10846958174904943],"monthlyWeightPct":[5.62,5.28,6.11,9.33,8.64,7.85,7.99,7.84,9.04,12.16,9.3,10.85],"monthlyForecastKg":[29559,27764,32118,49091,45447,41265,42030,41244,47536,63975,48916,57055],"recommendations":{"conservative":447400,"normal":526000,"optimistic":604700},"recommendedTargetKg":526000,"dominantModel":"Tren Tahunan Berbobot (fallback)","models":[{"key":"weightedTrend","name":"Tren Tahunan Berbobot","forecastKg":460611,"weightPct":50,"mape":null,"biasPct":null,"periods":0},{"key":"robustSeasonal","name":"Tren Robust Musiman","forecastKg":580162,"weightPct":35,"mape":null,"biasPct":null,"periods":0},{"key":"holtWinters","name":"Holt-Winters Musiman","forecastKg":617908,"weightPct":15,"mape":null,"biasPct":null,"periods":0}],"anomalyCount":0,"uncertaintyPct":14.95,"modelDispersionPct":14.95,"weightingBasis":"Bobot fallback adaptif untuk 2 tahun data","biasCorrectionPct":0,"backtest":{"available":false,"periods":0,"mape":null,"maeKg":null,"biasPct":null},"note":"Backtest belum cukup. Sistem memakai bobot fallback adaptif dan transparan untuk 2 tahun data; rentang ketidakpastian juga memperhitungkan selisih prediksi antar-model.","message":""} | T2: 46192.489 | U2: V3_TARGET_ENSEMBLE_MONTHLY_BACKTEST_SAFE | V2: Target produksi fallback adaptif 2 tahun optimistis tahun 2026 — histori 2024, 2025 | W2: active | X2: 46187.638 | Y2: 46191.608

Sheet ARCHIVE_TARGET_PRODUKSI
A1: tahun | B1: target_kg | C1: jan_kg | D1: feb_kg | E1: mar_kg | F1: apr_kg | G1: mei_kg | H1: jun_kg | I1: jul_kg | J1: agu_kg | K1: sep_kg | L1: okt_kg | M1: nov_kg | N1: des_kg | O1: target_source | P1: recommendation_level | Q1: analysis_years | R1: analysis_quality | S1: smart_version | T1: keterangan | U1: status | V1: created_at | W1: updated_at | X1: archived_at | Y1: archive_version | Z1: closed_year | AA1: closed_to_year | AB1: close_year_batch_id

Sheet YEAR_STATUS
A1: periode_tahun | B1: status_tahun | C1: locked | D1: closed_at | E1: closed_by | F1: backup_file | G1: backup_file_id | H1: backup_generated_at | I1: summary_json | J1: version | K1: updated_at | L1: catatan
A2: 2026 | B2: OPEN | C2: FALSE | J2: V3_YEAR_CLOSING_8F_ROLLBACK_ACTIVE_2026_SAFE | K2: 46182.573 | L2: Rollback 8F: 2026 dikembalikan sebagai tahun berjalan OPEN karena operasional masih 2026.

Sheet SOURCE_2026_RAW
A1: Januari | B1: PANEN 1 | C1: x | D1: harga | E1: Jumlah | F1: BIAYA 1 | G1: keterangan | H1: Jumlah | I1: keterangan | J1: Jumlah | K1: pinjaman | L1: Jumlah
A2: 46378 | B2: 3,753 Kg | C2: x | D2: 3.08 | E2: Rp 11,559,240 | F2: ongkos mobil | G2: 21.753 x Rp 120 | H2: Rp 2,610,360 | I2: kas | J2: Rp 14,000,000
B3: 3,194 Kg | C3: x | D3: 3.08 | E3: Rp 9,837,520 | F3: upah panen | G3: 21.753 x Rp 170 | H3: Rp 3,698,010 | I3: panen 1 | J3: Rp 66,922,800
B4: 6,230 Kg | C4: x | D4: 3.08 | E4: Rp 19,188,400 | F4: brondolan | H4: 700 | I4: biaya 1 | J4: Rp 31,133,370
B5: 4,754 Kg | C5: x | D5: 3.08 | E5: Rp 14,642,320 | F5: SPSI | H5: 250 | I5: pinjaman | J5: Rp 6,000,000
B6: 3,822 Kg | C6: x | D6: 3.06 | E6: Rp 11,695,320 | F6: borate | G6: 29 karung x 490.000 | H6: Rp 14,210,000 | I6: potong pinjaman
E7: ⏳ | F7: premi pupuk | H7: Rp 1,400,000
B8: 21,753 Kg | E8: Rp 66,922,800 | F8: PLN | H8: 220 | I8: total | J8: Rp 43,789,430
F9: injektor hilux | H9: Rp 4,715,000 | I9: transfer | J9: Rp 43,789,430
F10: bibit | H10: Rp 2,000,000 | I10: sisa | J10: Rp -
F11: berobat anggota | H11: 100
F12: beras | H12: Rp 1,230,000
I14: Profit: | J14: Rp 35,789,430
G18: total | H18: Rp 31,133,370
A19: Januari | B19: PANEN 2 | C19: x | D19: harga | E19: Jumlah | F19: BIAYA 2 | G19: keterangan | H19: Jumlah | I19: keterangan | J19: Jumlah | K19: pinjaman | L19: Jumlah
A20: 46026 | B20: 5,278 Kg | C20: x | D20: 3.08 | E20: Rp 16,256,240 | F20: ongkos mobil | G20: 18.207 x Rp 120 | H20: Rp 2,184,840 | I20: kas
B21: 5,392 Kg | C21: x | D21: 3.08 | E21: Rp 16,607,360 | F21: upah panen | G21: 18.207 x Rp 170 | H21: Rp 3,095,190 | I21: panen 2 | J21: Rp 55,851,450
B22: 4,511 Kg | C22: x | D22: 3.05 | E22: Rp 13,758,550 | F22: brondolan | H22: 700 | I22: biaya 2 | J22: Rp 23,185,030
B23: 3,026 Kg | C23: x | D23: 3.05 | E23: Rp 9,229,300 | F23: SPSI | H23: 200 | I23: pinjaman
E24: ⏳ | F24: gaji along, ijal | H24: Rp 4,500,000 | I24: potong pinjaman | J24: Rp 6,000,000
E25: ⏳ | F25: durian | H25: 500
B26: 18,207 Kg | E26: Rp 55,851,450 | F26: jangkos | H26: Rp 6,000,000 | I26: total | J26: Rp 38,666,420
F27: babat | G27: 1,4 Ha x 750.000 | H27: Rp 1,050,000 | I27: transfer | J27: Rp 32,000,000
F28: lansir | H28: 750 | I28: sisa | J28: Rp 6,666,420
F29: ayam tahun baru | H29: 330
F30: kabel PLN | H30: 100
F31: babat | G31: harian | H31: 800
F32: tunas | G32: 850 btg x 3.500 | H32: Rp 2,975,000 | I32: Profit | J32: Rp 32,666,420
G36: total | H36: Rp 23,185,030
A37: Februari | B37: PANEN 1 | C37: x | D37: harga | E37: Jumlah | F37: BIAYA 1 | G37: keterangan | H37: Jumlah | I37: keterangan | J37: Jumlah | K37: pinjaman | L37: Jumlah
A38: 46041 | B38: 3,464 Kg | C38: x | D38: 3.07 | E38: Rp 10,634,480 | F38: ongkos mobil | G38: 20.807 x Rp 120 | H38: Rp 2,496,840 | I38: kas | J38: Rp 6,000,000
B39: 2,172 Kg | C39: x | D39: 3.09 | E39: Rp 6,711,480 | F39: upah panen | G39: 20.807 x Rp 170 | H39: Rp 3,537,190 | I39: panen 1 | J39: Rp 64,103,490
B40: 5,287 Kg | C40: x | D40: 3.09 | E40: Rp 16,336,830 | F40: brondolan | H40: 700 | I40: biaya 1 | J40: Rp 25,689,030
B41: 6,043 Kg | C41: x | D41: 3.07 | E41: Rp 18,552,010 | F41: SPSI | H41: 250 | I41: pinjaman | J41: Rp 6,000,000
B42: 3,841 Kg | C42: x | D42: 3.09 | E42: Rp 11,868,690 | F42: dolomit | G42: 128 karung x 50.000 | H42: Rp 6,400,000 | I42: potong pinjaman
E43: ⏳ | F43: premi pupuk | H43: Rp 3,200,000
B44: 20,807 Kg | E44: Rp 64,103,490 | F44: ongkos pupuk | H44: 400 | I44: total | J44: Rp 38,414,460
F45: PLN | G45: 2 kali | H45: 220 | I45: transfer | J45: Rp 23,000,000
F46: mancang | H46: 150 | I46: sisa | J46: Rp 15,414,460
F47: kir hilux + service | H47: Rp 1,785,000
...

Sheet TX_BIAYA
A1: tx_id | B1: created_at | C1: updated_at | D1: status | E1: periode_tahun | F1: periode_bulan | G1: tanggal_bukti | H1: kategori | I1: biaya | J1: keterangan | K1: jumlah | L1: sumber_file | M1: source_row | N1: panen_ke | O1: batch_id
A2: V3-BIAYA-2026-01-0001 | B2: 2026-06-07T12:09:16.098Z | C2: 2026-06-07T12:09:16.098Z | D2: active | E2: 2026 | F2: 1 | G2: 46013 | H2: panen | I2: ongkos mobil | J2: 21.753 x Rp 120 | K2: 2610360 | L2: BUKIT PRAGO - 2026 / harian | M2: 2 | N2: 1
A3: V3-BIAYA-2026-01-0002 | B3: 2026-06-07T12:09:16.098Z | C3: 2026-06-07T12:09:16.098Z | D3: active | E3: 2026 | F3: 1 | G3: 46013 | H3: panen | I3: upah panen | J3: 21.753 x Rp 170 | K3: 3698010 | L3: BUKIT PRAGO - 2026 / harian | M3: 3 | N3: 1
A4: V3-BIAYA-2026-01-0003 | B4: 2026-06-07T12:09:16.098Z | C4: 2026-06-07T12:09:16.098Z | D4: active | E4: 2026 | F4: 1 | G4: 46013 | H4: panen | I4: brondolan | K4: 700000 | L4: BUKIT PRAGO - 2026 / harian | M4: 4 | N4: 1
A5: V3-BIAYA-2026-01-0004 | B5: 2026-06-07T12:09:16.098Z | C5: 2026-06-07T12:09:16.098Z | D5: active | E5: 2026 | F5: 1 | G5: 46013 | H5: panen | I5: SPSI | K5: 250000 | L5: BUKIT PRAGO - 2026 / harian | M5: 5 | N5: 1
A6: V3-BIAYA-2026-01-0005 | B6: 2026-06-07T12:09:16.098Z | C6: 2026-06-07T12:09:16.098Z | D6: active | E6: 2026 | F6: 1 | G6: 46013 | H6: pupuk | I6: borate | J6: 29 karung x 490.000 | K6: 14210000 | L6: BUKIT PRAGO - 2026 / harian | M6: 6 | N6: 1
A7: V3-BIAYA-2026-01-0006 | B7: 2026-06-07T12:09:16.098Z | C7: 2026-06-07T12:09:16.098Z | D7: active | E7: 2026 | F7: 1 | G7: 46013 | H7: pupuk | I7: premi pupuk | K7: 1400000 | L7: BUKIT PRAGO - 2026 / harian | M7: 7 | N7: 1
A8: V3-BIAYA-2026-01-0007 | B8: 2026-06-07T12:09:16.098Z | C8: 2026-06-07T12:09:16.098Z | D8: active | E8: 2026 | F8: 1 | G8: 46013 | H8: alat_bbm_mesin | I8: PLN | K8: 220000 | L8: BUKIT PRAGO - 2026 / harian | M8: 8 | N8: 1
A9: V3-BIAYA-2026-01-0008 | B9: 2026-06-07T12:09:16.098Z | C9: 2026-06-07T12:09:16.098Z | D9: active | E9: 2026 | F9: 1 | G9: 46013 | H9: alat_bbm_mesin | I9: injektor hilux | K9: 4715000 | L9: BUKIT PRAGO - 2026 / harian | M9: 9 | N9: 1
A10: V3-BIAYA-2026-01-0009 | B10: 2026-06-07T12:09:16.098Z | C10: 2026-06-07T12:09:16.098Z | D10: active | E10: 2026 | F10: 1 | G10: 46013 | H10: serba_serbi | I10: bibit | K10: 2000000 | L10: BUKIT PRAGO - 2026 / harian | M10: 10 | N10: 1
A11: V3-BIAYA-2026-01-0010 | B11: 2026-06-07T12:09:16.098Z | C11: 2026-06-07T12:09:16.098Z | D11: active | E11: 2026 | F11: 1 | G11: 46013 | H11: serba_serbi | I11: berobat anggota | K11: 100000 | L11: BUKIT PRAGO - 2026 / harian | M11: 11 | N11: 1
A12: V3-BIAYA-2026-01-0011 | B12: 2026-06-07T12:09:16.098Z | C12: 2026-06-07T12:09:16.098Z | D12: active | E12: 2026 | F12: 1 | G12: 46013 | H12: serba_serbi | I12: beras | K12: 1230000 | L12: BUKIT PRAGO - 2026 / harian | M12: 12 | N12: 1
A13: V3-BIAYA-2026-01-0012 | B13: 2026-06-07T12:09:16.102Z | C13: 2026-06-07T12:09:16.102Z | D13: active | E13: 2026 | F13: 1 | G13: 46026 | H13: panen | I13: ongkos mobil | J13: 18.207 x Rp 120 | K13: 2184840 | L13: BUKIT PRAGO - 2026 / harian | M13: 20 | N13: 2
A14: V3-BIAYA-2026-01-0013 | B14: 2026-06-07T12:09:16.102Z | C14: 2026-06-07T12:09:16.102Z | D14: active | E14: 2026 | F14: 1 | G14: 46026 | H14: panen | I14: upah panen | J14: 18.207 x Rp 170 | K14: 3095190 | L14: BUKIT PRAGO - 2026 / harian | M14: 21 | N14: 2
A15: V3-BIAYA-2026-01-0014 | B15: 2026-06-07T12:09:16.102Z | C15: 2026-06-07T12:09:16.102Z | D15: active | E15: 2026 | F15: 1 | G15: 46026 | H15: panen | I15: brondolan | K15: 700000 | L15: BUKIT PRAGO - 2026 / harian | M15: 22 | N15: 2
A16: V3-BIAYA-2026-01-0015 | B16: 2026-06-07T12:09:16.102Z | C16: 2026-06-07T12:09:16.102Z | D16: active | E16: 2026 | F16: 1 | G16: 46026 | H16: panen | I16: SPSI | K16: 200000 | L16: BUKIT PRAGO - 2026 / harian | M16: 23 | N16: 2
A17: V3-BIAYA-2026-01-0016 | B17: 2026-06-07T12:09:16.103Z | C17: 2026-06-07T12:09:16.103Z | D17: active | E17: 2026 | F17: 1 | G17: 46026 | H17: tenaga_kerja | I17: gaji along, ijal | K17: 4500000 | L17: BUKIT PRAGO - 2026 / harian | M17: 24 | N17: 2
A18: V3-BIAYA-2026-01-0017 | B18: 2026-06-07T12:09:16.103Z | C18: 2026-06-07T12:09:16.103Z | D18: active | E18: 2026 | F18: 1 | G18: 46026 | H18: serba_serbi | I18: durian | K18: 500000 | L18: BUKIT PRAGO - 2026 / harian | M18: 25 | N18: 2
A19: V3-BIAYA-2026-01-0018 | B19: 2026-06-07T12:09:16.103Z | C19: 2026-06-07T12:09:16.103Z | D19: active | E19: 2026 | F19: 1 | G19: 46026 | H19: jangkos | I19: jangkos | K19: 6000000 | L19: BUKIT PRAGO - 2026 / harian | M19: 26 | N19: 2
A20: V3-BIAYA-2026-01-0019 | B20: 2026-06-07T12:09:16.103Z | C20: 2026-06-07T12:09:16.103Z | D20: active | E20: 2026 | F20: 1 | G20: 46026 | H20: perawatan | I20: babat | J20: 1,4 Ha x 750.000 | K20: 1050000 | L20: BUKIT PRAGO - 2026 / harian | M20: 27 | N20: 2
A21: V3-BIAYA-2026-01-0020 | B21: 2026-06-07T12:09:16.103Z | C21: 2026-06-07T12:09:16.103Z | D21: active | E21: 2026 | F21: 1 | G21: 46026 | H21: panen | I21: lansir | K21: 750000 | L21: BUKIT PRAGO - 2026 / harian | M21: 28 | N21: 2
A22: V3-BIAYA-2026-01-0021 | B22: 2026-06-07T12:09:16.103Z | C22: 2026-06-07T12:09:16.103Z | D22: active | E22: 2026 | F22: 1 | G22: 46026 | H22: serba_serbi | I22: ayam tahun baru | K22: 330000 | L22: BUKIT PRAGO - 2026 / harian | M22: 29 | N22: 2
A23: V3-BIAYA-2026-01-0022 | B23: 2026-06-07T12:09:16.103Z | C23: 2026-06-07T12:09:16.103Z | D23: active | E23: 2026 | F23: 1 | G23: 46026 | H23: alat_bbm_mesin | I23: kabel PLN | K23: 100000 | L23: BUKIT PRAGO - 2026 / harian | M23: 30 | N23: 2
A24: V3-BIAYA-2026-01-0023 | B24: 2026-06-07T12:09:16.103Z | C24: 2026-06-07T12:09:16.103Z | D24: active | E24: 2026 | F24: 1 | G24: 46026 | H24: perawatan | I24: babat | J24: harian | K24: 800000 | L24: BUKIT PRAGO - 2026 / harian | M24: 31 | N24: 2
A25: V3-BIAYA-2026-01-0024 | B25: 2026-06-07T12:09:16.103Z | C25: 2026-06-07T12:09:16.103Z | D25: active | E25: 2026 | F25: 1 | G25: 46026 | H25: perawatan | I25: tunas | J25: 850 btg x 3.500 | K25: 2975000 | L25: BUKIT PRAGO - 2026 / harian | M25: 32 | N25: 2
A26: V3-BIAYA-2026-02-0001 | B26: 2026-06-07T12:09:16.106Z | C26: 2026-06-07T12:09:16.106Z | D26: active | E26: 2026 | F26: 1 | G26: 46041 | H26: panen | I26: ongkos mobil | J26: 20.807 x Rp 120 | K26: 2496840 | L26: BUKIT PRAGO - 2026 / harian | M26: 38 | N26: 3
A27: V3-BIAYA-2026-02-0002 | B27: 2026-06-07T12:09:16.106Z | C27: 2026-06-07T12:09:16.106Z | D27: active | E27: 2026 | F27: 1 | G27: 46041 | H27: panen | I27: upah panen | J27: 20.807 x Rp 170 | K27: 3537190 | L27: BUKIT PRAGO - 2026 / harian | M27: 39 | N27: 3
A28: V3-BIAYA-2026-02-0003 | B28: 2026-06-07T12:09:16.106Z | C28: 2026-06-07T12:09:16.106Z | D28: active | E28: 2026 | F28: 1 | G28: 46041 | H28: panen | I28: brondolan | K28: 700000 | L28: BUKIT PRAGO - 2026 / harian | M28: 40 | N28: 3
A29: V3-BIAYA-2026-02-0004 | B29: 2026-06-07T12:09:16.106Z | C29: 2026-06-07T12:09:16.106Z | D29: active | E29: 2026 | F29: 1 | G29: 46041 | H29: panen | I29: SPSI | K29: 250000 | L29: BUKIT PRAGO - 2026 / harian | M29: 41 | N29: 3
A30: V3-BIAYA-2026-02-0005 | B30: 2026-06-07T12:09:16.106Z | C30: 2026-06-07T12:09:16.106Z | D30: active | E30: 2026 | F30: 1 | G30: 46041 | H30: pupuk | I30: dolomit | J30: 128 karung x 50.000 | K30: 6400000 | L30: BUKIT PRAGO - 2026 / harian | M30: 42 | N30: 3
A31: V3-BIAYA-2026-02-0006 | B31: 2026-06-07T12:09:16.106Z | C31: 2026-06-07T12:09:16.106Z | D31: active | E31: 2026 | F31: 1 | G31: 46041 | H31: pupuk | I31: premi pupuk | K31: 3200000 | L31: BUKIT PRAGO - 2026 / harian | M31: 43 | N31: 3
A32: V3-BIAYA-2026-02-0007 | B32: 2026-06-07T12:09:16.106Z | C32: 2026-06-07T12:09:16.106Z | D32: active | E32: 2026 | F32: 1 | G32: 46041 | H32: pupuk | I32: ongkos pupuk | K32: 400000 | L32: BUKIT PRAGO - 2026 / harian | M32: 44 | N32: 3
A33: V3-BIAYA-2026-02-0008 | B33: 2026-06-07T12:09:16.106Z | C33: 2026-06-07T12:09:16.106Z | D33: active | E33: 2026 | F33: 1 | G33: 46041 | H33: alat_bbm_mesin | I33: PLN | J33: 2 kali | K33: 220000 | L33: BUKIT PRAGO - 2026 / harian | M33: 45 | N33: 3
A34: V3-BIAYA-2026-02-0009 | B34: 2026-06-07T12:09:16.106Z | C34: 2026-06-07T12:09:16.106Z | D34: active | E34: 2026 | F34: 1 | G34: 46041 | H34: perawatan | I34: mancang | K34: 150000 | L34: BUKIT PRAGO - 2026 / harian | M34: 46 | N34: 3
A35: V3-BIAYA-2026-02-0010 | B35: 2026-06-07T12:09:16.106Z | C35: 2026-06-07T12:09:16.106Z | D35: active | E35: 2026 | F35: 1 | G35: 46041 | H35: alat_bbm_mesin | I35: kir hilux + service | K35: 1785000 | L35: BUKIT PRAGO - 2026 / harian | M35: 47 | N35: 3
A36: V3-BIAYA-2026-02-0011 | B36: 2026-06-07T12:09:16.106Z | C36: 2026-06-07T12:09:16.106Z | D36: active | E36: 2026 | F36: 1 | G36: 46041 | H36: serba_serbi | I36: lunas pintu + pasang | J36: 4.300.000 + 1.500.000 | K36: 5800000 | L36: BUKIT PRAGO - 2026 / harian | M36: 48 | N36: 3
A37: V3-BIAYA-2026-02-0012 | B37: 2026-06-07T12:09:16.106Z | C37: 2026-06-07T12:09:16.106Z | D37: active | E37: 2026 | F37: 1 | G37: 46041 | H37: panen | I37: lansir | K37: 750000 | L37: BUKIT PRAGO - 2026 / harian | M37: 49 | N37: 3
A38: V3-BIAYA-2026-02-0013 | B38: 2026-06-07T12:09:16.109Z | C38: 2026-06-07T12:09:16.109Z | D38: active | E38: 2026 | F38: 2 | G38: 46055 | H38: panen | I38: ongkos mobil | J38: 20.534 x Rp 120 | K38: 2464080 | L38: BUKIT PRAGO - 2026 / harian | M38: 56 | N38: 1
A39: V3-BIAYA-2026-02-0014 | B39: 2026-06-07T12:09:16.109Z | C39: 2026-06-07T12:09:16.109Z | D39: active | E39: 2026 | F39: 2 | G39: 46055 | H39: panen | I39: upah panen | J39: 20.534 x Rp 170 | K39: 3490780 | L39: BUKIT PRAGO - 2026 / harian | M39: 57 | N39: 1
A40: V3-BIAYA-2026-02-0015 | B40: 2026-06-07T12:09:16.109Z | C40: 2026-06-07T12:09:16.109Z | D40: active | E40: 2026 | F40: 2 | G40: 46055 | H40: panen | I40: brondolan | K40: 700000 | L40: BUKIT PRAGO - 2026 / harian | M40: 58 | N40: 1
...

Sheet TX_KAS
A1: tx_id | B1: created_at | C1: updated_at | D1: status | E1: periode_tahun | F1: periode_bulan | G1: tanggal_bukti | H1: jenis_kas | I1: keterangan | J1: jumlah | K1: akun_sumber | L1: akun_tujuan | M1: sumber_file | N1: source_row | O1: panen_ke | P1: batch_id
A2: V3-KAS-2026-01-0001 | B2: 2026-06-07T12:09:16.098Z | C2: 2026-06-07T12:09:16.098Z | D2: active | E2: 2026 | F2: 1 | G2: 46013 | H2: kas_masuk | I2: Januari PANEN 1 - kas | J2: 14000000 | K2: kas_kebun | L2: kas_kebun | M2: BUKIT PRAGO - 2026 / harian | N2: 2 | O2: 1
A3: V3-KAS-2026-01-0002 | B3: 2026-06-07T12:09:16.098Z | C3: 2026-06-07T12:09:16.098Z | D3: active | E3: 2026 | F3: 1 | G3: 46013 | H3: pinjaman | I3: Januari PANEN 1 - pinjaman | J3: 6000000 | K3: kas_kebun | L3: kas_kebun | M3: BUKIT PRAGO - 2026 / harian | N3: 5 | O3: 1
A4: V3-KAS-2026-01-0003 | B4: 2026-06-07T12:09:16.098Z | C4: 2026-06-07T12:09:16.098Z | D4: active | E4: 2026 | F4: 1 | G4: 46013 | H4: transfer | I4: Januari PANEN 1 - transfer | J4: 43789430 | K4: kas_kebun | L4: kas_kebun | M4: BUKIT PRAGO - 2026 / harian | N4: 9 | O4: 1
A5: V3-KAS-2026-01-0004 | B5: 2026-06-07T12:09:16.103Z | C5: 2026-06-07T12:09:16.103Z | D5: active | E5: 2026 | F5: 1 | G5: 46026 | H5: potong_pinjaman | I5: Januari PANEN 2 - potong pinjaman | J5: 6000000 | K5: kas_kebun | L5: kas_kebun | M5: BUKIT PRAGO - 2026 / harian | N5: 24 | O5: 2
A6: V3-KAS-2026-01-0005 | B6: 2026-06-07T12:09:16.103Z | C6: 2026-06-07T12:09:16.103Z | D6: active | E6: 2026 | F6: 1 | G6: 46026 | H6: transfer | I6: Januari PANEN 2 - transfer | J6: 32000000 | K6: kas_kebun | L6: kas_kebun | M6: BUKIT PRAGO - 2026 / harian | N6: 27 | O6: 2
A7: V3-KAS-2026-02-0001 | B7: 2026-06-07T12:09:16.106Z | C7: 2026-06-07T12:09:16.106Z | D7: active | E7: 2026 | F7: 1 | G7: 46041 | H7: kas_masuk | I7: Januari PANEN 3 - kas | J7: 6000000 | K7: kas_kebun | L7: kas_kebun | M7: BUKIT PRAGO - 2026 / harian | N7: 38 | O7: 3
A8: V3-KAS-2026-02-0002 | B8: 2026-06-07T12:09:16.106Z | C8: 2026-06-07T12:09:16.106Z | D8: active | E8: 2026 | F8: 1 | G8: 46041 | H8: pinjaman | I8: Januari PANEN 3 - pinjaman | J8: 6000000 | K8: kas_kebun | L8: kas_kebun | M8: BUKIT PRAGO - 2026 / harian | N8: 41 | O8: 3
A9: V3-KAS-2026-02-0003 | B9: 2026-06-07T12:09:16.106Z | C9: 2026-06-07T12:09:16.106Z | D9: active | E9: 2026 | F9: 1 | G9: 46041 | H9: transfer | I9: Januari PANEN 3 - transfer | J9: 23000000 | K9: kas_kebun | L9: kas_kebun | M9: BUKIT PRAGO - 2026 / harian | N9: 45 | O9: 3
A10: V3-KAS-2026-02-0004 | B10: 2026-06-07T12:09:16.109Z | C10: 2026-06-07T12:09:16.109Z | D10: active | E10: 2026 | F10: 2 | G10: 46055 | H10: kas_masuk | I10: Februari PANEN 1 - kas | J10: 15000000 | K10: kas_kebun | L10: kas_kebun | M10: BUKIT PRAGO - 2026 / harian | N10: 56 | O10: 1
A11: V3-KAS-2026-02-0005 | B11: 2026-06-07T12:09:16.109Z | C11: 2026-06-07T12:09:16.109Z | D11: active | E11: 2026 | F11: 2 | G11: 46055 | H11: potong_pinjaman | I11: Februari PANEN 1 - potong pinjaman | J11: 6000000 | K11: kas_kebun | L11: kas_kebun | M11: BUKIT PRAGO - 2026 / harian | N11: 60 | O11: 1
A12: V3-KAS-2026-03-0001 | B12: 2026-06-07T12:09:16.111Z | C12: 2026-06-07T12:09:16.111Z | D12: active | E12: 2026 | F12: 2 | G12: 46068 | H12: kas_masuk | I12: Februari PANEN 2 - kas | J12: 32000000 | K12: kas_kebun | L12: kas_kebun | M12: BUKIT PRAGO - 2026 / harian | N12: 74 | O12: 2
A13: V3-KAS-2026-03-0002 | B13: 2026-06-07T12:09:16.112Z | C13: 2026-06-07T12:09:16.112Z | D13: active | E13: 2026 | F13: 2 | G13: 46068 | H13: pinjaman | I13: Februari PANEN 2 - pinjaman | J13: 4000000 | K13: kas_kebun | L13: kas_kebun | M13: BUKIT PRAGO - 2026 / harian | N13: 77 | O13: 2
... A34: V3-KAS-2026-06-0006 | B34: 2026-06-07T12:09:16.128Z | C34: 2026-06-07T12:09:16.128Z | D34: active | E34: 2026 | F34: 6 | G34: 46179 | H34: transfer | I34: Juni PANEN 1 - transfer | J34: 57000000 | K34: kas_kebun | L34: kas_kebun | M34: BUKIT PRAGO - 2026 / harian | N34: 207 | O34: 1
A35: KAS_V3INPUT_2026_6_PANEN2_20260618_222734_001 | B35: 46191.936 | D35: active | E35: 2026 | F35: 6 | G35: 46191 | H35: kas_masuk | I35: Juni PANEN 2 - kas | J35: 14811340 | N35: INPUT_SHEET_V3 | O35: 2 | P35: V3INPUT_2026_6_PANEN2_20260618_222734
A36: KAS_V3INPUT_2026_6_PANEN2_20260618_222734_002 | B36: 46191.936 | D36: active | E36: 2026 | F36: 6 | G36: 46191 | H36: potong_pinjaman | I36: Juni PANEN 2 - potong pinjaman | J36: 5000000 | N36: INPUT_SHEET_V3 | O36: 2 | P36: V3INPUT_2026_6_PANEN2_20260618_222734
A37: KAS_V3INPUT_2026_6_PANEN2_20260618_222734_003 | B37: 46191.936 | D37: active | E37: 2026 | F37: 6 | G37: 46191 | H37: transfer | I37: Juni PANEN 2 - transfer | J37: 75000000 | N37: INPUT_SHEET_V3 | O37: 2 | P37: V3INPUT_2026_6_PANEN2_20260618_222734
A38: KAS_V3INPUT_2026_7_PANEN1_20260702_210109_001 | B38: 46205.876 | D38: active | E38: 2026 | F38: 7 | G38: 46205 | H38: kas_masuk | I38: Juli PANEN 1 - kas | J38: 14000000 | N38: INPUT_SHEET_V3 | O38: 1 | P38: V3INPUT_2026_7_PANEN1_20260702_210109
A39: KAS_V3INPUT_2026_7_PANEN1_20260702_210109_002 | B39: 46205.876 | D39: active | E39: 2026 | F39: 7 | G39: 46205 | H39: pinjaman | I39: Juli PANEN 1 - pinjaman | J39: 10411000 | N39: INPUT_SHEET_V3 | O39: 1 | P39: V3INPUT_2026_7_PANEN1_20260702_210109
A40: KAS_V3INPUT_2026_7_PANEN1_20260702_210109_003 | B40: 46205.876 | D40: active | E40: 2026 | F40: 7 | G40: 46205 | H40: transfer | I40: Juli PANEN 1 - transfer | J40: 66000000 | N40: INPUT_SHEET_V3 | O40: 1 | P40: V3INPUT_2026_7_PANEN1_20260702_210109

Sheet TX_PEMUPUKAN
A1: tx_id | B1: created_at | C1: updated_at | D1: status | E1: periode_tahun | F1: periode_bulan | G1: tanggal_bukti | H1: jenis_pupuk | I1: dosis | J1: status_realisasi | K1: keterangan | L1: sumber_file | M1: source_row | N1: batch_id | O1: jumlah | P1: satuan | Q1: blok_area
A2: PUPUK_V3PUPUK_2026_1_20260609_080733_001 | B2: 46182.339 | C2: 46182.339 | D2: active | E2: 2026 | F2: 1 | G2: 46031 | H2: Dolomit | I2: 1.25 | J2: Selesai | K2: semester 1 | M2: INPUT_PEMUPUKAN_V3 | N2: V3PUPUK_2026_1_20260609_080733 | O2: 130 | P2: sak | Q2: semua
A3: PUPUK_V3PUPUK_2026_6_20260611_114318_001 | B3: 46184.488 | C3: 46184.488 | D3: active | E3: 2026 | F3: 1 | G3: 46042 | H3: RP | I3: 1.25 | J3: Selesai | K3: semester 1 | M3: INPUT_PEMUPUKAN_V3 | N3: V3PUPUK_2026_6_20260611_114318 | O3: 130 | P3: sak | Q3: semua
A4: PUPUK_V3PUPUK_2026_2_20260612_102401_001 | B4: 46185.433 | C4: 46185.433 | D4: active | E4: 2026 | F4: 2 | G4: 46059 | H4: Urea | I4: 0.75 | J4: Selesai | K4: semester 1 | M4: INPUT_PEMUPUKAN_V3 | N4: V3PUPUK_2026_2_20260612_102401 | O4: 91 | P4: sak | Q4: semua
A5: PUPUK_V3PUPUK_2026_2_20260612_181231_001 | B5: 46185.759 | C5: 46185.759 | D5: active | E5: 2026 | F5: 3 | G5: 46084 | H5: Borate | I5: 0.07 | J5: Selesai | K5: semester 1 | M5: INPUT_PEMUPUKAN_V3 | N5: V3PUPUK_2026_2_20260612_181231 | O5: 16 | P5: sak | Q5: semua
A6: PUPUK_V3PUPUK_2026_4_20260612_204833_001 | B6: 46185.867 | C6: 46185.867 | D6: active | E6: 2026 | F6: 4 | G6: 46115 | H6: Abu Jangkos / KCL Abu | I6: 2 | J6: Selesai | K6: semester 1 | M6: INPUT_PEMUPUKAN_V3 | N6: V3PUPUK_2026_4_20260612_204833 | O6: 12000 | P6: kg | Q6: semua
A7: PUPUK_V3PUPUK_2026_5_20260612_205026_001 | B7: 46185.868 | C7: 46185.868 | D7: active | E7: 2026 | F7: 5 | G7: 46154 | H7: Humat | I7: 1 | J7: Selesai | K7: semester 1 | M7: INPUT_PEMUPUKAN_V3 | N7: V3PUPUK_2026_5_20260612_205026 | O7: 6 | P7: sak | Q7: semua
A8: PUPUK_V3PUPUK_2026_5_20260612_205246_001 | B8: 46185.87 | C8: 46185.87 | D8: active | E8: 2026 | F8: 5 | G8: 46154 | H8: Amonium Klorida | I8: 1 | J8: Selesai | K8: semester 1 | M8: INPUT_PEMUPUKAN_V3 | N8: V3PUPUK_2026_5_20260612_205246 | O8: 112 | P8: sak | Q8: semua
A9: PUPUK_V3PUPUK_2026_7_20260702_212108_001 | B9: 46205.89 | C9: 46205.89 | D9: active | E9: 2026 | F9: 7 | G9: 46207 | H9: Abu Jangkos | I9: 2 | J9: Selesai | K9: semester 1 | M9: INPUT_PEMUPUKAN_V3 | N9: V3PUPUK_2026_7_20260702_212108 | O9: 12710 | P9: kg | Q9: semua

Sheet STAGING_2024_PENJUALAN
A1: periode_bulan | B1: tanggal_bukti | C1: panen_ke | D1: panen_kg | E1: harga | F1: jumlah | G1: keterangan
A2: 1 | C2: 1 | D2: 5567 | E2: 2180 | F2: 12136060 | G2: Januari PANEN 1
A3: 1 | C3: 1 | D3: 4652 | E3: 2160 | F3: 10048320 | G3: Januari PANEN 1
A4: 1 | C4: 2 | D4: 4588 | E4: 2270 | F4: 10414760 | G4: Januari PANEN 2
A5: 1 | C5: 2 | D5: 3418 | E5: 2270 | F5: 7758860 | G5: Januari PANEN 2
A6: 2 | C6: 1 | D6: 3172 | E6: 2420 | F6: 7676240 | G6: Februari PANEN 1
A7: 2 | C7: 1 | D7: 4413 | E7: 2420 | F7: 10679460 | G7: Februari PANEN 1
A8: 2 | C8: 2 | D8: 4478 | E8: 2360 | F8: 10568080 | G8: Februari PANEN 2
A9: 2 | C9: 2 | D9: 3343 | E9: 2360 | F9: 7889480 | G9: Februari PANEN 2
A10: 3 | C10: 1 | D10: 4219 | E10: 2380 | F10: 10041220 | G10: Maret PANEN 1
A11: 3 | C11: 1 | D11: 4894 | E11: 2380 | F11: 11647720 | G11: Maret PANEN 1
A12: 3 | C12: 2 | D12: 4650 | E12: 2480 | F12: 11532000 | G12: Maret PANEN 2
A13: 3 | C13: 2 | D13: 5510 | E13: 2480 | F13: 13664800 | G13: Maret PANEN 2
... A76: 12 | C76: 2 | D76: 1128 | E76: 3130 | F76: 3530640 | G76: Desember PANEN 2

Sheet STAGING_2024_BIAYA
A1: periode_bulan | B1: tanggal_bukti | C1: panen_ke | D1: kategori | E1: biaya | F1: keterangan | G1: jumlah
A2: 1 | C2: 1 | D2: panen | E2: ongkos mobil | F2: Januari PANEN 1 | G2: 1021000
A3: 1 | C3: 1 | D3: panen | E3: upah panen | F3: Januari PANEN 1 | G3: 1700000
A4: 1 | C4: 1 | D4: panen | E4: brondolan | F4: Januari PANEN 1 | G4: 300000
A5: 1 | C5: 1 | D5: panen | E5: SPSI | F5: Januari PANEN 1 | G5: 100000
A6: 1 | C6: 1 | D6: alat_bbm_mesin | E6: PLN | F6: Januari PANEN 1 | G6: 110000
A7: 1 | C7: 1 | D7: pupuk | E7: pupuk NPK | F7: 25 karung x 395.000 | G7: 9875000
A8: 1 | C8: 1 | D8: serba_serbi | E8: serba serbi | F8: Januari PANEN 1 | G8: 3960000
A9: 1 | C9: 2 | D9: panen | E9: ongkos mobil | F9: Januari PANEN 2 | G9: 800000
A10: 1 | C10: 2 | D10: panen | E10: upah panen | F10: Januari PANEN 2 | G10: 1361000
A11: 1 | C11: 2 | D11: panen | E11: brondolan | F11: Januari PANEN 2 | G11: 300000
A12: 1 | C12: 2 | D12: panen | E12: SPSI | F12: Januari PANEN 2 | G12: 100000
A13: 1 | C13: 2 | D13: serba_serbi | E13: gaji along, ijal | F13: Januari PANEN 2 | G13: 6600000
... A193: 12 | C193: 2 | D193: serba_serbi | E193: serba serbi | F193: Desember PANEN 2 | G193: 475000

Sheet STAGING_2024_KAS
A1: periode_bulan | B1: tanggal_bukti | C1: panen_ke | D1: jenis_kas | E1: keterangan | F1: jumlah | G1: akun_sumber | H1: akun_tujuan

Sheet STAGING_2024_PEMUPUKAN
A1: periode_bulan | B1: tanggal_bukti | C1: jenis_pupuk | D1: dosis | E1: satuan | F1: jumlah | G1: blok_area | H1: keterangan | I1: status_realisasi

Sheet ARCHIVE_PENJUALAN
A1: tx_id | B1: status | C1: periode_tahun | D1: periode_bulan | E1: tanggal_bukti | F1: panen_ke | G1: panen_kg | H1: harga | I1: jumlah | J1: keterangan | K1: source_row | L1: archived_at | M1: archive_version | N1: created_at | O1: updated_at | P1: sumber_file | Q1: batch_id | R1: archive_source | S1: closed_year | T1: closed_to_year | U1: close_year_batch_id
A2: ARCH2025_JUAL_01_P1 | B2: active | C2: 2025 | D2: 1 | E2: 46010 | F2: 1 | G2: 11887 | H2: 3244 | I2: 38558880 | J2: Januari - Panen 1 | K2: SOURCE_2025_HARIAN | L2: 46183.423 | M2: V3_ARCHIVE_SEPARATE_STORAGE_3_IMPORT_SAFE
A3: ARCH2025_JUAL_01_P2 | B3: active | C3: 2025 | D3: 1 | E3: 46044 | F3: 2 | G3: 14299 | H3: 2941 | I3: 42056380 | J3: Januari - Panen 2 | K3: SOURCE_2025_HARIAN | L3: 46183.423 | M3: V3_ARCHIVE_SEPARATE_STORAGE_3_IMPORT_SAFE
A4: ARCH2025_JUAL_02_P1 | B4: active | C4: 2025 | D4: 2 | E4: 46055 | F4: 1 | G4: 11609 | H4: 2879 | I4: 33418400 | J4: Februari - Panen 1 | K4: SOURCE_2025_HARIAN | L4: 46183.423 | M4: V3_ARCHIVE_SEPARATE_STORAGE_3_IMPORT_SAFE
A5: ARCH2025_JUAL_02_P2 | B5: active | C5: 2025 | D5: 2 | E5: 46069 | F5: 2 | G5: 13123 | H5: 3078 | I5: 40394870 | J5: Februari - Panen 2 | K5: SOURCE_2025_HARIAN | L5: 46183.423 | M5: V3_ARCHIVE_SEPARATE_STORAGE_3_IMPORT_SAFE
A6: ARCH2025_JUAL_03_P1 | B6: active | C6: 2025 | D6: 3 | E6: 46085 | F6: 1 | G6: 14724 | H6: 3351 | I6: 49338560 | J6: Maret - Panen 1 | K6: SOURCE_2025_HARIAN | L6: 46183.423 | M6: V3_ARCHIVE_SEPARATE_STORAGE_3_IMPORT_SAFE
A7: ARCH2025_JUAL_03_P2 | B7: active | C7: 2025 | D7: 3 | E7: 46099 | F7: 2 | G7: 13832 | H7: 3335 | I7: 46134940 | J7: Maret - Panen 2 | K7: SOURCE_2025_HARIAN | L7: 46183.423 | M7: V3_ARCHIVE_SEPARATE_STORAGE_3_IMPORT_SAFE
A8: ARCH2025_JUAL_04_P1 | B8: active | C8: 2025 | D8: 4 | E8: 46113 | F8: 1 | G8: 24197 | H8: 3170 | I8: 76710090 | J8: April - Panen 1 | K8: SOURCE_2025_HARIAN | L8: 46183.423 | M8: V3_ARCHIVE_SEPARATE_STORAGE_3_IMPORT_SAFE
A9: ARCH2025_JUAL_04_P2 | B9: active | C9: 2025 | D9: 4 | E9: 46120 | F9: 2 | G9: 33431 | H9: 3036 | I9: 101503050 | J9: April - Panen 2 | K9: SOURCE_2025_HARIAN | L9: 46183.423 | M9: V3_ARCHIVE_SEPARATE_STORAGE_3_IMPORT_SAFE
A10: ARCH2025_JUAL_05_P1 | B10: active | C10: 2025 | D10: 5 | E10: 46134 | F10: 1 | G10: 23107 | H10: 3025 | I10: 69888710 | J10: Mei - Panen 1 | K10: SOURCE_2025_HARIAN | L10: 46183.423 | M10: V3_ARCHIVE_SEPARATE_STORAGE_3_IMPORT_SAFE
A11: ARCH2025_JUAL_05_P2 | B11: active | C11: 2025 | D11: 5 | E11: 46148 | F11: 2 | G11: 16806 | H11: 2981 | I11: 50104190 | J11: Mei - Panen 2 | K11: SOURCE_2025_HARIAN | L11: 46183.423 | M11: V3_ARCHIVE_SEPARATE_STORAGE_3_IMPORT_SAFE
A12: ARCH2025_JUAL_06_P1 | B12: active | C12: 2025 | D12: 6 | E12: 46187 | F12: 1 | G12: 17188 | H12: 2827 | I12: 48590390 | J12: Juni - Panen 1 | K12: SOURCE_2025_HARIAN | L12: 46183.423 | M12: V3_ARCHIVE_SEPARATE_STORAGE_3_IMPORT_SAFE
A13: ARCH2025_JUAL_06_P2 | B13: active | C13: 2025 | D13: 6 | E13: 46201 | F13: 2 | G13: 16989 | H13: 2899 | I13: 49252970 | J13: Juni - Panen 2 | K13: SOURCE_2025_HARIAN | L13: 46183.423 | M13: V3_ARCHIVE_SEPARATE_STORAGE_3_IMPORT_SAFE
... A25: ARCH2025_JUAL_12_P2 | B25: active | C25: 2025 | D25: 12 | E25: 46375 | F25: 2 | G25: 25409 | H25: 3106 | I25: 78917740 | J25: Desember - Panen 2 | K25: SOURCE_2025_HARIAN | L25: 46183.423 | M25: V3_ARCHIVE_SEPARATE_STORAGE_3_IMPORT_SAFE
A26: IMP2024_PENJUALAN_000001 | B26: active | C26: 2024 | D26: 1 | F26: 1 | G26: 5567 | H26: 2180 | I26: 12136060 | J26: Januari PANEN 1 | K26: IMPORT_ARCHIVE_2024_USING_2025_PATTERN_STAGE_A | L26: 46185.845 | M26: V3_CLEAN_FULL_REWRITE_ACTIVE_ARCHIVE_SAFE | Q26: IMPORT_ARCHIVE_2024_USING_2025_PATTERN | R26: IMPORT_ARCHIVE_2024 | S26: 2024 | U26: IMPORT_ARCHIVE_2024_20260612_201620
A27: IMP2024_PENJUALAN_000002 | B27: active | C27: 2024 | D27: 1 | F27: 1 | G27: 4652 | H27: 2160 | I27: 10048320 | J27: Januari PANEN 1 | K27: IMPORT_ARCHIVE_2024_USING_2025_PATTERN_STAGE_A | L27: 46185.845 | M27: V3_CLEAN_FULL_REWRITE_ACTIVE_ARCHIVE_SAFE | Q27: IMPORT_ARCHIVE_2024_USING_2025_PATTERN | R27: IMPORT_ARCHIVE_2024 | S27: 2024 | U27: IMPORT_ARCHIVE_2024_20260612_201620
A28: IMP2024_PENJUALAN_000003 | B28: active | C28: 2024 | D28: 1 | F28: 2 | G28: 4588 | H28: 2270 | I28: 10414760 | J28: Januari PANEN 2 | K28: IMPORT_ARCHIVE_2024_USING_2025_PATTERN_STAGE_A | L28: 46185.845 | M28: V3_CLEAN_FULL_REWRITE_ACTIVE_ARCHIVE_SAFE | Q28: IMPORT_ARCHIVE_2024_USING_2025_PATTERN | R28: IMPORT_ARCHIVE_2024 | S28: 2024 | U28: IMPORT_ARCHIVE_2024_20260612_201620
A29: IMP2024_PENJUALAN_000004 | B29: active | C29: 2024 | D29: 1 | F29: 2 | G29: 3418 | H29: 2270 | I29: 7758860 | J29: Januari PANEN 2 | K29: IMPORT_ARCHIVE_2024_USING_2025_PATTERN_STAGE_A | L29: 46185.845 | M29: V3_CLEAN_FULL_REWRITE_ACTIVE_ARCHIVE_SAFE | Q29: IMPORT_ARCHIVE_2024_USING_2025_PATTERN | R29: IMPORT_ARCHIVE_2024 | S29: 2024 | U29: IMPORT_ARCHIVE_2024_20260612_201620
A30: IMP2024_PENJUALAN_000005 | B30: active | C30: 2024 | D30: 2 | F30: 1 | G30: 3172 | H30: 2420 | I30: 7676240 | J30: Februari PANEN 1 | K30: IMPORT_ARCHIVE_2024_USING_2025_PATTERN_STAGE_A | L30: 46185.845 | M30: V3_CLEAN_FULL_REWRITE_ACTIVE_ARCHIVE_SAFE | Q30: IMPORT_ARCHIVE_2024_USING_2025_PATTERN | R30: IMPORT_ARCHIVE_2024 | S30: 2024 | U30: IMPORT_ARCHIVE_2024_20260612_201620
A31: IMP2024_PENJUALAN_000006 | B31: active | C31: 2024 | D31: 2 | F31: 1 | G31: 4413 | H31: 2420 | I31: 10679460 | J31: Februari PANEN 1 | K31: IMPORT_ARCHIVE_2024_USING_2025_PATTERN_STAGE_A | L31: 46185.845 | M31: V3_CLEAN_FULL_REWRITE_ACTIVE_ARCHIVE_SAFE | Q31: IMPORT_ARCHIVE_2024_USING_2025_PATTERN | R31: IMPORT_ARCHIVE_2024 | S31: 2024 | U31: IMPORT_ARCHIVE_2024_20260612_201620
A32: IMP2024_PENJUALAN_000007 | B32: active | C32: 2024 | D32: 2 | F32: 2 | G32: 4478 | H32: 2360 | I32: 10568080 | J32: Februari PANEN 2 | K32: IMPORT_ARCHIVE_2024_USING_2025_PATTERN_STAGE_A | L32: 46185.845 | M32: V3_CLEAN_FULL_REWRITE_ACTIVE_ARCHIVE_SAFE | Q32: IMPORT_ARCHIVE_2024_USING_2025_PATTERN | R32: IMPORT_ARCHIVE_2024 | S32: 2024 | U32: IMPORT_ARCHIVE_2024_20260612_201620
A33: IMP2024_PENJUALAN_000008 | B33: active | C33: 2024 | D33: 2 | F33: 2 | G33: 3343 | H33: 2360 | I33: 7889480 | J33: Februari PANEN 2 | K33: IMPORT_ARCHIVE_2024_USING_2025_PATTERN_STAGE_A | L33: 46185.845 | M33: V3_CLEAN_FULL_REWRITE_ACTIVE_ARCHIVE_SAFE | Q33: IMPORT_ARCHIVE_2024_USING_2025_PATTERN | R33: IMPORT_ARCHIVE_2024 | S33: 2024 | U33: IMPORT_ARCHIVE_2024_20260612_201620
A34: IMP2024_PENJUALAN_000009 | B34: active | C34: 2024 | D34: 3 | F34: 1 | G34: 4219 | H34: 2380 | I34: 10041220 | J34: Maret PANEN 1 | K34: IMPORT_ARCHIVE_2024_USING_2025_PATTERN_STAGE_A | L34: 46185.845 | M34: V3_CLEAN_FULL_REWRITE_ACTIVE_ARCHIVE_SAFE | Q34: IMPORT_ARCHIVE_2024_USING_2025_PATTERN | R34: IMPORT_ARCHIVE_2024 | S34: 2024 | U34: IMPORT_ARCHIVE_2024_20260612_201620
A35: IMP2024_PENJUALAN_000010 | B35: active | C35: 2024 | D35: 3 | F35: 1 | G35: 4894 | H35: 2380 | I35: 11647720 | J35: Maret PANEN 1 | K35: IMPORT_ARCHIVE_2024_USING_2025_PATTERN_STAGE_A | L35: 46185.845 | M35: V3_CLEAN_FULL_REWRITE_ACTIVE_ARCHIVE_SAFE | Q35: IMPORT_ARCHIVE_2024_USING_2025_PATTERN | R35: IMPORT_ARCHIVE_2024 | S35: 2024 | U35: IMPORT_ARCHIVE_2024_20260612_201620
A36: IMP2024_PENJUALAN_000011 | B36: active | C36: 2024 | D36: 3 | F36: 2 | G36: 4650 | H36: 2480 | I36: 11532000 | J36: Maret PANEN 2 | K36: IMPORT_ARCHIVE_2024_USING_2025_PATTERN_STAGE_A | L36: 46185.845 | M36: V3_CLEAN_FULL_REWRITE_ACTIVE_ARCHIVE_SAFE | Q36: IMPORT_ARCHIVE_2024_USING_2025_PATTERN | R36: IMPORT_ARCHIVE_2024 | S36: 2024 | U36: IMPORT_ARCHIVE_2024_20260612_201620
A37: IMP2024_PENJUALAN_000012 | B37: active | C37: 2024 | D37: 3 | F37: 2 | G37: 5510 | H37: 2480 | I37: 13664800 | J37: Maret PANEN 2 | K37: IMPORT_ARCHIVE_2024_USING_2025_PATTERN_STAGE_A | L37: 46185.845 | M37: V3_CLEAN_FULL_REWRITE_ACTIVE_ARCHIVE_SAFE | Q37: IMPORT_ARCHIVE_2024_USING_2025_PATTERN | R37: IMPORT_ARCHIVE_2024 | S37: 2024 | U37: IMPORT_ARCHIVE_2024_20260612_201620
... A100: IMP2024_PENJUALAN_000075 | B100: active | C100: 2024 | D100: 12 | F100: 2 | G100: 1128 | H100: 3130 | I100: 3530640 | J100: Desember PANEN 2 | K100: IMPORT_ARCHIVE_2024_USING_2025_PATTERN_STAGE_A | L100: 46185.845 | M100: V3_CLEAN_FULL_REWRITE_ACTIVE_ARCHIVE_SAFE | Q100: IMPORT_ARCHIVE_2024_USING_2025_PATTERN | R100: IMPORT_ARCHIVE_2024 | S100: 2024 | U100: IMPORT_ARCHIVE_2024_20260612_201620

Sheet ARCHIVE_BIAYA
A1: tx_id | B1: status | C1: periode_tahun | D1: periode_bulan | E1: tanggal_bukti | F1: panen_ke | G1: kategori | H1: biaya | I1: keterangan | J1: jumlah | K1: source_row | L1: archived_at | M1: archive_version | N1: created_at | O1: updated_at | P1: sumber_file | Q1: batch_id | R1: archive_source | S1: closed_year | T1: closed_to_year | U1: close_year_batch_id
A2: ARCH2025_BIAYA_01_P1_0001 | B2: active | C2: 2025 | D2: 1 | E2: 46010 | F2: 1 | G2: panen | H2: ongkos mobil | I2: 11.887 x 120 | J2: 1350000 | K2: SOURCE_2025_HARIAN | L2: 46183.423 | M2: V3_ARCHIVE_SEPARATE_STORAGE_3_IMPORT_SAFE
A3: ARCH2025_BIAYA_01_P1_0002 | B3: active | C3: 2025 | D3: 1 | E3: 46010 | F3: 1 | G3: panen | H3: upah panen | I3: 11.887 x 170 | J3: 2640000 | K3: SOURCE_2025_HARIAN | L3: 46183.423 | M3: V3_ARCHIVE_SEPARATE_STORAGE_3_IMPORT_SAFE
A4: ARCH2025_BIAYA_01_P1_0003 | B4: active | C4: 2025 | D4: 1 | E4: 46010 | F4: 1 | G4: panen | H4: brondolan | J4: 400000 | K4: SOURCE_2025_HARIAN | L4: 46183.423 | M4: V3_ARCHIVE_SEPARATE_STORAGE_3_IMPORT_SAFE
A5: ARCH2025_BIAYA_01_P1_0004 | B5: active | C5: 2025 | D5: 1 | E5: 46010 | F5: 1 | G5: panen | H5: SPSI | J5: 150000 | K5: SOURCE_2025_HARIAN | L5: 46183.423 | M5: V3_ARCHIVE_SEPARATE_STORAGE_3_IMPORT_SAFE
A6: ARCH2025_BIAYA_01_P1_0005 | B6: active | C6: 2025 | D6: 1 | E6: 46010 | F6: 1 | G6: serba_serbi | H6: ganti oli | J6: 825000 | K6: SOURCE_2025_HARIAN | L6: 46183.423 | M6: V3_ARCHIVE_SEPARATE_STORAGE_3_IMPORT_SAFE
A7: ARCH2025_BIAYA_01_P1_0006 | B7: active | C7: 2025 | D7: 1 | E7: 46010 | F7: 1 | G7: serba_serbi | H7: beras | J7: 1096000 | K7: SOURCE_2025_HARIAN | L7: 46183.423 | M7: V3_ARCHIVE_SEPARATE_STORAGE_3_IMPORT_SAFE
A8: ARCH2025_BIAYA_01_P1_0007 | B8: active | C8: 2025 | D8: 1 | E8: 46010 | F8: 1 | G8: panen | H8: egrek | J8: 295000 | K8: SOURCE_2025_HARIAN | L8: 46183.423 | M8: V3_ARCHIVE_SEPARATE_STORAGE_3_IMPORT_SAFE
A9: ARCH2025_BIAYA_01_P1_0008 | B9: active | C9: 2025 | D9: 1 | E9: 46010 | F9: 1 | G9: serba_serbi | H9: durian | J9: 665000 | K9: SOURCE_2025_HARIAN | L9: 46183.423 | M9: V3_ARCHIVE_SEPARATE_STORAGE_3_IMPORT_SAFE
A10: ARCH2025_BIAYA_01_P1_0009 | B10: active | C10: 2025 | D10: 1 | E10: 46010 | F10: 1 | G10: jangkos | H10: jangkos | J10: 4500000 | K10: SOURCE_2025_HARIAN | L10: 46183.423 | M10: V3_ARCHIVE_SEPARATE_STORAGE_3_IMPORT_SAFE
A11: ARCH2025_BIAYA_01_P1_0010 | B11: active | C11: 2025 | D11: 1 | E11: 46010 | F11: 1 | G11: serba_serbi | H11: PLN | J11: 110000 | K11: SOURCE_2025_HARIAN | L11: 46183.423 | M11: V3_ARCHIVE_SEPARATE_STORAGE_3_IMPORT_SAFE
A12: ARCH2025_BIAYA_01_P1_0011 | B12: active | C12: 2025 | D12: 1 | E12: 46010 | F12: 1 | G12: serba_serbi | H12: lampu | J12: 50000 | K12: SOURCE_2025_HARIAN | L12: 46183.423 | M12: V3_ARCHIVE_SEPARATE_STORAGE_3_IMPORT_SAFE
A13: ARCH2025_BIAYA_01_P1_0012 | B13: active | C13: 2025 | D13: 1 | E13: 46010 | F13: 1 | G13: serba_serbi | H13: berobat | J13: 240000 | K13: SOURCE_2025_HARIAN | L13: 46183.423 | M13: V3_ARCHIVE_SEPARATE_STORAGE_3_IMPORT_SAFE
A14: ARCH2025_BIAYA_01_P2_0013 | B14: active | C14: 2025 | D14: 1 | E14: 46044 | F14: 2 | G14: panen | H14: ongkos mobil | I14: 14.299 x 120 | J14: 1494000 | K14: SOURCE_2025_HARIAN | L14: 46183.423 | M14: V3_ARCHIVE_SEPARATE_STORAGE_3_IMPORT_SAFE
A15: ARCH2025_BIAYA_01_P2_0014 | B15: active | C15: 2025 | D15: 1 | E15: 46044 | F15: 2 | G15: panen | H15: upah panen | I15: 14.299 x 170 | J15: 2880000 | K15: SOURCE_2025_HARIAN | L15: 46183.423 | M15: V3_ARCHIVE_SEPARATE_STORAGE_3_IMPORT_SAFE
A16: ARCH2025_BIAYA_01_P2_0015 | B16: active | C16: 2025 | D16: 1 | E16: 46044 | F16: 2 | G16: panen | H16: brondolan | J16: 400000 | K16: SOURCE_2025_HARIAN | L16: 46183.423 | M16: V3_ARCHIVE_SEPARATE_STORAGE_3_IMPORT_SAFE
A17: ARCH2025_BIAYA_01_P2_0016 | B17: active | C17: 2025 | D17: 1 | E17: 46044 | F17: 2 | G17: panen | H17: SPSI | J17: 150000 | K17: SOURCE_2025_HARIAN | L17: 46183.423 | M17: V3_ARCHIVE_SEPARATE_STORAGE_3_IMPORT_SAFE
A18: ARCH2025_BIAYA_01_P2_0017 | B18: active | C18: 2025 | D18: 1 | E18: 46044 | F18: 2 | G18: serba_serbi | H18: gaji along, ijal | J18: 3500000 | K18: SOURCE_2025_HARIAN | L18: 46183.423 | M18: V3_ARCHIVE_SEPARATE_STORAGE_3_IMPORT_SAFE
A19: ARCH2025_BIAYA_01_P2_0018 | B19: active | C19: 2025 | D19: 1 | E19: 46044 | F19: 2 | G19: perawatan | H19: lansir | J19: 2000000 | K19: SOURCE_2025_HARIAN | L19: 46183.423 | M19: V3_ARCHIVE_SEPARATE_STORAGE_3_IMPORT_SAFE
A20: ARCH2025_BIAYA_01_P2_0019 | B20: active | C20: 2025 | D20: 1 | E20: 46044 | F20: 2 | G20: serba_serbi | H20: PLN | J20: 110000 | K20: SOURCE_2025_HARIAN | L20: 46183.423 | M20: V3_ARCHIVE_SEPARATE_STORAGE_3_IMPORT_SAFE
A21: ARCH2025_BIAYA_01_P2_0020 | B21: active | C21: 2025 | D21: 1 | E21: 46044 | F21: 2 | G21: perawatan | H21: tunas | J21: 4029000 | K21: SOURCE_2025_HARIAN | L21: 46183.423 | M21: V3_ARCHIVE_SEPARATE_STORAGE_3_IMPORT_SAFE
A22: ARCH2025_BIAYA_01_P2_0021 | B22: active | C22: 2025 | D22: 1 | E22: 46044 | F22: 2 | G22: perawatan | H22: babat | J22: 7750000 | K22: SOURCE_2025_HARIAN | L22: 46183.423 | M22: V3_ARCHIVE_SEPARATE_STORAGE_3_IMPORT_SAFE
A23: ARCH2025_BIAYA_02_P1_0022 | B23: active | C23: 2025 | D23: 2 | E23: 46055 | F23: 1 | G23: panen | H23: ongkos mobil | I23: 11.609 x 120 | J23: 1377000 | K23: SOURCE_2025_HARIAN | L23: 46183.423 | M23: V3_ARCHIVE_SEPARATE_STORAGE_3_IMPORT_SAFE
A24: ARCH2025_BIAYA_02_P1_0023 | B24: active | C24: 2025 | D24: 2 | E24: 46055 | F24: 1 | G24: panen | H24: upah panen | I24: 11.609 x 170 | J24: 2423090 | K24: SOURCE_2025_HARIAN | L24: 46183.423 | M24: V3_ARCHIVE_SEPARATE_STORAGE_3_IMPORT_SAFE
A25: ARCH2025_BIAYA_02_P1_0024 | B25: active | C25: 2025 | D25: 2 | E25: 46055 | F25: 1 | G25: panen | H25: brondolan | J25: 400000 | K25: SOURCE_2025_HARIAN | L25: 46183.423 | M25: V3_ARCHIVE_SEPARATE_STORAGE_3_IMPORT_SAFE
A26: ARCH2025_BIAYA_02_P1_0025 | B26: active | C26: 2025 | D26: 2 | E26: 46055 | F26: 1 | G26: panen | H26: SPSI | J26: 100000 | K26: SOURCE_2025_HARIAN | L26: 46183.423 | M26: V3_ARCHIVE_SEPARATE_STORAGE_3_IMPORT_SAFE
A27: ARCH2025_BIAYA_02_P1_0026 | B27: active | C27: 2025 | D27: 2 | E27: 46055 | F27: 1 | G27: serba_serbi | H27: papan | J27: 1800000 | K27: SOURCE_2025_HARIAN | L27: 46183.423 | M27: V3_ARCHIVE_SEPARATE_STORAGE_3_IMPORT_SAFE
A28: ARCH2025_BIAYA_02_P1_0027 | B28: active | C28: 2025 | D28: 2 | E28: 46055 | F28: 1 | G28: serba_serbi | H28: beras | J28: 982000 | K28: SOURCE_2025_HARIAN | L28: 46183.423 | M28: V3_ARCHIVE_SEPARATE_STORAGE_3_IMPORT_SAFE
A29: ARCH2025_BIAYA_02_P1_0028 | B29: active | C29: 2025 | D29: 2 | E29: 46055 | F29: 1 | G29: batu | H29: pasir kem | J29: 1700000 | K29: SOURCE_2025_HARIAN | L29: 46183.423 | M29: V3_ARCHIVE_SEPARATE_STORAGE_3_IMPORT_SAFE
A30: ARCH2025_BIAYA_02_P1_0029 | B30: active | C30: 2025 | D30: 2 | E30: 46055 | F30: 1 | G30: serba_serbi | H30: PLN | J30: 110000 | K30: SOURCE_2025_HARIAN | L30: 46183.423 | M30: V3_ARCHIVE_SEPARATE_STORAGE_3_IMPORT_SAFE
A31: ARCH2025_BIAYA_02_P1_0030 | B31: active | C31: 2025 | D31: 2 | E31: 46055 | F31: 1 | G31: perawatan | H31: tunas | J31: 880000 | K31: SOURCE_2025_HARIAN | L31: 46183.423 | M31: V3_ARCHIVE_SEPARATE_STORAGE_3_IMPORT_SAFE
A32: ARCH2025_BIAYA_02_P1_0031 | B32: active | C32: 2025 | D32: 2 | E32: 46055 | F32: 1 | G32: pupuk | H32: dolomit | I32: 130 karrung x 50.000 | J32: 6500000 | K32: SOURCE_2025_HARIAN | L32: 46183.423 | M32: V3_ARCHIVE_SEPARATE_STORAGE_3_IMPORT_SAFE
A33: ARCH2025_BIAYA_02_P1_0032 | B33: active | C33: 2025 | D33: 2 | E33: 46055 | F33: 1 | G33: perawatan | H33: lansir | J33: 1000000 | K33: SOURCE_2025_HARIAN | L33: 46183.423 | M33: V3_ARCHIVE_SEPARATE_STORAGE_3_IMPORT_SAFE
A34: ARCH2025_BIAYA_02_P1_0033 | B34: active | C34: 2025 | D34: 2 | E34: 46055 | F34: 1 | G34: serba_serbi | H34: pajak mobil | J34: 5600000 | K34: SOURCE_2025_HARIAN | L34: 46183.423 | M34: V3_ARCHIVE_SEPARATE_STORAGE_3_IMPORT_SAFE
A35: ARCH2025_BIAYA_02_P1_0034 | B35: active | C35: 2025 | D35: 2 | E35: 46055 | F35: 1 | G35: perawatan | H35: babat | J35: 325000 | K35: SOURCE_2025_HARIAN | L35: 46183.423 | M35: V3_ARCHIVE_SEPARATE_STORAGE_3_IMPORT_SAFE
A36: ARCH2025_BIAYA_02_P2_0035 | B36: active | C36: 2025 | D36: 2 | E36: 46069 | F36: 2 | G36: panen | H36: ongkos mobil | I36: 13.123 x 120 | J36: 1126000 | K36: SOURCE_2025_HARIAN | L36: 46183.423 | M36: V3_ARCHIVE_SEPARATE_STORAGE_3_IMPORT_SAFE
A37: ARCH2025_BIAYA_02_P2_0036 | B37: active | C37: 2025 | D37: 2 | E37: 46069 | F37: 2 | G37: panen | H37: upah panen | I37: 13.123 x 170 | J37: 2681000 | K37: SOURCE_2025_HARIAN | L37: 46183.423 | M37: V3_ARCHIVE_SEPARATE_STORAGE_3_IMPORT_SAFE
A38: ARCH2025_BIAYA_02_P2_0037 | B38: active | C38: 2025 | D38: 2 | E38: 46069 | F38: 2 | G38: panen | H38: brondolan | J38: 400000 | K38: SOURCE_2025_HARIAN | L38: 46183.423 | M38: V3_ARCHIVE_SEPARATE_STORAGE_3_IMPORT_SAFE
A39: ARCH2025_BIAYA_02_P2_0038 | B39: active | C39: 2025 | D39: 2 | E39: 46069 | F39: 2 | G39: panen | H39: SPSI | J39: 150000 | K39: SOURCE_2025_HARIAN | L39: 46183.423 | M39: V3_ARCHIVE_SEPARATE_STORAGE_3_IMPORT_SAFE
A40: ARCH2025_BIAYA_02_P2_0039 | B40: active | C40: 2025 | D40: 2 | E40: 46069 | F40: 2 | G40: serba_serbi | H40: gaji along, ijal | J40: 3500000 | K40: SOURCE_2025_HARIAN | L40: 46183.423 | M40: V3_ARCHIVE_SEPARATE_STORAGE_3_IMPORT_SAFE
...

Sheet ARCHIVE_KAS
A1: tx_id | B1: status | C1: periode_tahun | D1: periode_bulan | E1: tanggal_bukti | F1: panen_ke | G1: jenis_kas | H1: keterangan | I1: jumlah | J1: akun_sumber | K1: akun_tujuan | L1: source_row | M1: archived_at | N1: archive_version | O1: created_at | P1: updated_at | Q1: sumber_file | R1: batch_id | S1: archive_source | T1: closed_year | U1: closed_to_year | V1: close_year_batch_id
A2: ARCH2025_KAS_03_P2_0001 | B2: active | C2: 2025 | D2: 3 | E2: 46099 | F2: 2 | G2: transfer | H2: transfer | I2: 25000000 | L2: SOURCE_2025_HARIAN | M2: 46183.423 | N2: V3_ARCHIVE_SEPARATE_STORAGE_3_IMPORT_SAFE
A3: ARCH2025_KAS_05_P1_0002 | B3: active | C3: 2025 | D3: 5 | E3: 46134 | F3: 1 | G3: kas_masuk | H3: kas | I3: 21000000 | L3: SOURCE_2025_HARIAN | M3: 46183.423 | N3: V3_ARCHIVE_SEPARATE_STORAGE_3_IMPORT_SAFE
A4: ARCH2025_KAS_05_P1_0003 | B4: active | C4: 2025 | D4: 5 | E4: 46134 | F4: 1 | G4: transfer | H4: transfer | I4: 29000000 | L4: SOURCE_2025_HARIAN | M4: 46183.423 | N4: V3_ARCHIVE_SEPARATE_STORAGE_3_IMPORT_SAFE
A5: ARCH2025_KAS_05_P2_0004 | B5: active | C5: 2025 | D5: 5 | E5: 46148 | F5: 2 | G5: kas_masuk | H5: kas | I5: 5282480 | L5: SOURCE_2025_HARIAN | M5: 46183.423 | N5: V3_ARCHIVE_SEPARATE_STORAGE_3_IMPORT_SAFE
A6: ARCH2025_KAS_05_P2_0005 | B6: active | C6: 2025 | D6: 5 | E6: 46148 | F6: 2 | G6: potong_pinjaman | H6: potong pinjaman | I6: 1897080 | L6: SOURCE_2025_HARIAN | M6: 46183.423 | N6: V3_ARCHIVE_SEPARATE_STORAGE_3_IMPORT_SAFE
A7: ARCH2025_KAS_06_P1_0006 | B7: active | C7: 2025 | D7: 6 | E7: 46187 | F7: 1 | G7: pinjaman | H7: pinjaman | I7: 7300000 | L7: SOURCE_2025_HARIAN | M7: 46183.423 | N7: V3_ARCHIVE_SEPARATE_STORAGE_3_IMPORT_SAFE
A8: ARCH2025_KAS_06_P2_0007 | B8: active | C8: 2025 | D8: 6 | E8: 46201 | F8: 2 | G8: pinjaman | H8: pinjaman | I8: 1500000 | L8: SOURCE_2025_HARIAN | M8: 46183.423 | N8: V3_ARCHIVE_SEPARATE_STORAGE_3_IMPORT_SAFE
A9: ARCH2025_KAS_06_P2_0008 | B9: active | C9: 2025 | D9: 6 | E9: 46201 | F9: 2 | G9: potong_pinjaman | H9: potong pinjaman | I9: 6300000 | L9: SOURCE_2025_HARIAN | M9: 46183.423 | N9: V3_ARCHIVE_SEPARATE_STORAGE_3_IMPORT_SAFE
A10: ARCH2025_KAS_07_P1_0009 | B10: active | C10: 2025 | D10: 7 | E10: 46213 | F10: 1 | G10: pinjaman | H10: pinjaman | I10: 4000000 | L10: SOURCE_2025_HARIAN | M10: 46183.423 | N10: V3_ARCHIVE_SEPARATE_STORAGE_3_IMPORT_SAFE
A11: ARCH2025_KAS_07_P2_0010 | B11: active | C11: 2025 | D11: 7 | E11: 46226 | F11: 2 | G11: kas_masuk | H11: kas | I11: 6726150 | L11: SOURCE_2025_HARIAN | M11: 46183.423 | N11: V3_ARCHIVE_SEPARATE_STORAGE_3_IMPORT_SAFE
A12: ARCH2025_KAS_07_P2_0011 | B12: active | C12: 2025 | D12: 7 | E12: 46226 | F12: 2 | G12: pinjaman | H12: pinjaman | I12: 1000000 | L12: SOURCE_2025_HARIAN | M12: 46183.423 | N12: V3_ARCHIVE_SEPARATE_STORAGE_3_IMPORT_SAFE
A13: ARCH2025_KAS_07_P2_0012 | B13: active | C13: 2025 | D13: 7 | E13: 46226 | F13: 2 | G13: potong_pinjaman | H13: potong pinjaman | I13: 5400000 | L13: SOURCE_2025_HARIAN | M13: 46183.423 | N13: V3_ARCHIVE_SEPARATE_STORAGE_3_IMPORT_SAFE
... A39: ARCH2025_KAS_12_P1_0038 | B39: active | C39: 2025 | D39: 12 | E39: 46350 | F39: 1 | G39: transfer | H39: transfer | I39: 62000000 | L39: SOURCE_2025_HARIAN | M39: 46183.423 | N39: V3_ARCHIVE_SEPARATE_STORAGE_3_IMPORT_SAFE

Sheet STAGING_PENJUALAN_ARCHIVE
A1: tx_id | B1: status | C1: periode_tahun | D1: periode_bulan | E1: tanggal_bukti | F1: panen_ke | G1: panen_kg | H1: harga | I1: jumlah | J1: keterangan | K1: source_row
A2: ARCH2025_JUAL_01_P1 | B2: active | C2: 2025 | D2: 1 | E2: 46375 | F2: 1 | G2: 11887 | H2: 3244 | I2: 38558880 | J2: Januari - Panen 1 | K2: SOURCE_2025_HARIAN
A3: ARCH2025_JUAL_01_P2 | B3: active | C3: 2025 | D3: 1 | E3: 46044 | F3: 2 | G3: 14299 | H3: 2941 | I3: 42056380 | J3: Januari - Panen 2 | K3: SOURCE_2025_HARIAN
A4: ARCH2025_JUAL_02_P1 | B4: active | C4: 2025 | D4: 2 | E4: 46055 | F4: 1 | G4: 11609 | H4: 2879 | I4: 33418400 | J4: Februari - Panen 1 | K4: SOURCE_2025_HARIAN
A5: ARCH2025_JUAL_02_P2 | B5: active | C5: 2025 | D5: 2 | E5: 46069 | F5: 2 | G5: 13123 | H5: 3078 | I5: 40394870 | J5: Februari - Panen 2 | K5: SOURCE_2025_HARIAN
A6: ARCH2025_JUAL_03_P1 | B6: active | C6: 2025 | D6: 3 | E6: 46085 | F6: 1 | G6: 14724 | H6: 3351 | I6: 49338560 | J6: Maret - Panen 1 | K6: SOURCE_2025_HARIAN
A7: ARCH2025_JUAL_03_P2 | B7: active | C7: 2025 | D7: 3 | E7: 46099 | F7: 2 | G7: 13832 | H7: 3335 | I7: 46134940 | J7: Maret - Panen 2 | K7: SOURCE_2025_HARIAN
A8: ARCH2025_JUAL_04_P1 | B8: active | C8: 2025 | D8: 4 | F8: 1 | G8: 24197 | H8: 3170 | I8: 76710090 | J8: April - Panen 1 | K8: SOURCE_2025_HARIAN
A9: ARCH2025_JUAL_04_P2 | B9: active | C9: 2025 | D9: 4 | E9: 46120 | F9: 2 | G9: 33431 | H9: 3036 | I9: 101503050 | J9: April - Panen 2 | K9: SOURCE_2025_HARIAN
A10: ARCH2025_JUAL_05_P1 | B10: active | C10: 2025 | D10: 5 | E10: 46134 | F10: 1 | G10: 23107 | H10: 3025 | I10: 69888710 | J10: Mei - Panen 1 | K10: SOURCE_2025_HARIAN
A11: ARCH2025_JUAL_05_P2 | B11: active | C11: 2025 | D11: 5 | E11: 46148 | F11: 2 | G11: 16806 | H11: 2981 | I11: 50104190 | J11: Mei - Panen 2 | K11: SOURCE_2025_HARIAN
A12: ARCH2025_JUAL_06_P1 | B12: active | C12: 2025 | D12: 6 | E12: 46187 | F12: 1 | G12: 17188 | H12: 2827 | I12: 48590390 | J12: Juni - Panen 1 | K12: SOURCE_2025_HARIAN
A13: ARCH2025_JUAL_06_P2 | B13: active | C13: 2025 | D13: 6 | E13: 46201 | F13: 2 | G13: 16989 | H13: 2899 | I13: 49252970 | J13: Juni - Panen 2 | K13: SOURCE_2025_HARIAN
A14: ARCH2025_JUAL_07_P1 | B14: active | C14: 2025 | D14: 7 | E14: 46213 | F14: 1 | G14: 17948 | H14: 3002 | I14: 53885040 | J14: Juli - Panen 1 | K14: SOURCE_2025_HARIAN
A15: ARCH2025_JUAL_07_P2 | B15: active | C15: 2025 | D15: 7 | E15: 46226 | F15: 2 | G15: 19270 | H15: 3180 | I15: 61285340 | J15: Juli - Panen 2 | K15: SOURCE_2025_HARIAN
A16: ARCH2025_JUAL_08_P1 | B16: active | C16: 2025 | D16: 8 | E16: 46240 | F16: 1 | G16: 18013 | H16: 3126 | I16: 56305250 | J16: Agustus - Panen 1 | K16: SOURCE_2025_HARIAN
A17: ARCH2025_JUAL_08_P2 | B17: active | C17: 2025 | D17: 8 | E17: 46253 | F17: 2 | G17: 20623 | H17: 3099 | I17: 63920640 | J17: Agustus - Panen 2 | K17: SOURCE_2025_HARIAN
A18: ARCH2025_JUAL_09_P1 | B18: active | C18: 2025 | D18: 9 | E18: 46267 | F18: 1 | G18: 23404 | H18: 3145 | I18: 73614770 | J18: September - Panen 1 | K18: SOURCE_2025_HARIAN
A19: ARCH2025_JUAL_09_P2 | B19: active | C19: 2025 | D19: 9 | E19: 46281 | F19: 2 | G19: 23430 | H19: 3189 | I19: 74714640 | J19: September - Panen 2 | K19: SOURCE_2025_HARIAN
A20: ARCH2025_JUAL_10_P1 | B20: active | C20: 2025 | D20: 10 | E20: 46295 | F20: 1 | G20: 24803 | H20: 3195 | I20: 79250320 | J20: Oktober - Panen 1 | K20: SOURCE_2025_HARIAN
... A25: ARCH2025_JUAL_12_P2 | B25: active | C25: 2025 | D25: 12 | E25: 46375 | F25: 2 | G25: 25409 | H25: 3106 | I25: 78917740 | J25: Desember - Panen 2 | K25: SOURCE_2025_HARIAN

Sheet STAGING_BIAYA_ARCHIVE
A1: tx_id | B1: status | C1: periode_tahun | D1: periode_bulan | E1: tanggal_bukti | F1: panen_ke | G1: kategori | H1: biaya | I1: keterangan | J1: jumlah | K1: source_row
A2: ARCH2025_BIAYA_01_P1_0001 | B2: active | C2: 2025 | D2: 1 | E2: 46375 | F2: 1 | G2: panen | H2: ongkos mobil | I2: 11.887 x 120 | J2: 1350000 | K2: SOURCE_2025_HARIAN
A3: ARCH2025_BIAYA_01_P1_0002 | B3: active | C3: 2025 | D3: 1 | E3: 46375 | F3: 1 | G3: panen | H3: upah panen | I3: 11.887 x 170 | J3: 2640000 | K3: SOURCE_2025_HARIAN
A4: ARCH2025_BIAYA_01_P1_0003 | B4: active | C4: 2025 | D4: 1 | E4: 46375 | F4: 1 | G4: panen | H4: brondolan | J4: 400000 | K4: SOURCE_2025_HARIAN
A5: ARCH2025_BIAYA_01_P1_0004 | B5: active | C5: 2025 | D5: 1 | E5: 46375 | F5: 1 | G5: panen | H5: SPSI | J5: 150000 | K5: SOURCE_2025_HARIAN
A6: ARCH2025_BIAYA_01_P1_0005 | B6: active | C6: 2025 | D6: 1 | E6: 46375 | F6: 1 | G6: serba_serbi | H6: ganti oli | J6: 825000 | K6: SOURCE_2025_HARIAN
A7: ARCH2025_BIAYA_01_P1_0006 | B7: active | C7: 2025 | D7: 1 | E7: 46375 | F7: 1 | G7: serba_serbi | H7: beras | J7: 1096000 | K7: SOURCE_2025_HARIAN
A8: ARCH2025_BIAYA_01_P1_0007 | B8: active | C8: 2025 | D8: 1 | E8: 46375 | F8: 1 | G8: panen | H8: egrek | J8: 295000 | K8: SOURCE_2025_HARIAN
